Workbook

Sheet EVSE Products-NY
A1: ID | B1: Name | C1: Description | D1: Manufacturer | E1: Unit Price ($) | F1: CSEV Cost ($) | G1: Annual Network Plan ($) | H1: Network Plan 1yr ($) | I1: Network Plan 3yr ($) | J1: Network Plan 5yr ($) | K1: Network Cost 1yr ($) | L1: Network Cost 3yr ($) | M1: Network Cost 5yr ($) | N1: Shipping ($) | O1: Number of Plugs | P1: Category | Q1: Charging Level | R1: calc1-ignore | S1: Warranty: 5-Yr Parts ONLY ($) | T1: calc2-ignore | U1: Warranty: 3-Yr FULL P&L ($) | V1: calc3-ignore | W1: Warranty: 5-Yr FULL P&L ($) | X1: 0.1
A2: csev-acpro-pedestal | B2: MaxiCharger ACPro - Pedestal | C2: Pedestal mount accessory for MaxiCharger ACPro | D2: Autel | E2: 1000 | F2: 500 | G2: 0 | H2: 0 | I2: 0 | J2: 0 | K2: 0 | L2: 0 | M2: 0 | N2: 0 | O2: 0 | P2: accessory | Q2: level2 | R2: 1000 | S2: =R2*(1+$X$1) -> 1100 | T2: 750 | U2: =T2*(1+$X$1) -> 825 | V2: 1250 | W2: =V2*(1+$X$1) -> 1375
A3: csev-acultra-cable-mgmt | B3: MaxiCharger ACUltra - Cable Management | C3: Cable management accessory for MaxiCharger ACUltra | D3: Autel | E3: 1000 | F3: 500 | G3: 0 | H3: 0 | I3: 0 | J3: 0 | K3: 0 | L3: 0 | M3: 0 | N3: 0 | O3: 0 | P3: accessory | Q3: level2 | R3: 1000 | S3: =R3*(1+$X$1) -> 1100 | T3: 750 | U3: =T3*(1+$X$1) -> 825 | V3: 1250 | W3: =V3*(1+$X$1) -> 1375
A4: csev-ac-sp-48a-pedestal | B4: MaxiCharger ACUltra - CSEV-AC-SP - 48A Output - Single Port Pedestal with CMS | C4: MaxiCharger ACUltra - CSEV-AC-SP - 48A Output - Single Port Pedestal with CMS. Includes 3 Years of Parts Only Warranty | D4: Autel | E4: 4423 | F4: 1580 | G4: 250 | H4: 250 | I4: 750 | J4: 1250 | K4: 150 | L4: 450 | M4: 750 | N4: 350 | O4: 1 | P4: charger | Q4: level2 | R4: =700*1.25 -> 875 | S4: =ROUNDUP(R4*(1+$X$1),-2) -> 1000 | T4: =500*1.25 -> 625 | U4: =ROUNDUP(T4*(1+$X$1),-2) -> 700 | V4: =900*1.25 -> 1125 | W4: =ROUNDUP(V4*(1+$X$1),-2) -> 1300
A5: csev-ac-sp-48a-wall | B5: MaxiCharger ACUltra - CSEV-AC-SP - 48A Output - Single Port Wall Mount | C5: MaxiCharger ACUltra - CSEV-AC-SP - 48A Output - Single Port Wall Mount. Includes 3 Years of Parts Only Warranty | D5: Autel | E5: 3173 | F5: 900 | G5: 250 | H5: 250 | I5: 750 | J5: 1250 | K5: 150 | L5: 450 | M5: 750 | N5: 350 | O5: 1 | P5: charger | Q5: level2 | R5: =700*1.25 -> 875 | S5: =ROUNDUP(R5*(1+$X$1),-2) -> 1000 | T5: =500*1.25 -> 625 | U5: =ROUNDUP(T5*(1+$X$1),-2) -> 700 | V5: =900*1.25 -> 1125 | W5: =ROUNDUP(V5*(1+$X$1),-2) -> 1300
A6: csev-ac-sp-40a-pedestal | B6: MaxiCharger ACUltra - CSEV-AC-SP - 40A Output - Single Port Pedestal with CMS | C6: MaxiCharger ACUltra - CSEV-AC-SP - 40A Output - Single Port Pedestal with CMS. Includes 3 Years of Parts Only Warranty | D6: Autel | E6: 4423 | F6: 1580 | G6: 250 | H6: 250 | I6: 750 | J6: 1250 | K6: 150 | L6: 450 | M6: 750 | N6: 350 | O6: 1 | P6: charger | Q6: level2 | R6: =700*1.25 -> 875 | S6: =ROUNDUP(R6*(1+$X$1),-2) -> 1000 | T6: =500*1.25 -> 625 | U6: =ROUNDUP(T6*(1+$X$1),-2) -> 700 | V6: =900*1.25 -> 1125 | W6: =ROUNDUP(V6*(1+$X$1),-2) -> 1300
A7: csev-ac-sp-40a-wall | B7: MaxiCharger ACUltra - CSEV-AC-SP - 40A Output - Single Port Wall Mount | C7: MaxiCharger ACUltra - CSEV-AC-SP - 40A Output - Single Port Wall Mount. Includes 3 Years of Parts Only Warranty | D7: Autel | E7: 3173 | F7: 900 | G7: 250 | H7: 250 | I7: 750 | J7: 1250 | K7: 150 | L7: 450 | M7: 750 | N7: 350 | O7: 1 | P7: charger | Q7: level2 | R7: =700*1.25 -> 875 | S7: =ROUNDUP(R7*(1+$X$1),-2) -> 1000 | T7: =500*1.25 -> 625 | U7: =ROUNDUP(T7*(1+$X$1),-2) -> 700 | V7: =900*1.25 -> 1125 | W7: =ROUNDUP(V7*(1+$X$1),-2) -> 1300
A8: csev-ac-sp-80a-pedestal | B8: MaxiCharger ACUltra - CSEV-AC-SP - 80A Output - Single Port Pedestal with CMS | C8: MaxiCharger ACUltra - CSEV-AC-SP - 80A Output - Single Port Pedestal with CMS. Includes 3 Years of Parts Only Warranty | D8: Autel | E8: 4423 | F8: 1580 | G8: 250 | H8: 250 | I8: 750 | J8: 1250 | K8: 150 | L8: 450 | M8: 750 | N8: 350 | O8: 1 | P8: charger | Q8: level2 | R8: =700*1.25 -> 875 | S8: =ROUNDUP(R8*(1+$X$1),-2) -> 1000 | T8: =500*1.25 -> 625 | U8: =ROUNDUP(T8*(1+$X$1),-2) -> 700 | V8: =900*1.25 -> 1125 | W8: =ROUNDUP(V8*(1+$X$1),-2) -> 1300
A9: csev-ac-sp-80a-wall | B9: MaxiCharger ACUltra - CSEV-AC-SP - 80A Output - Single Port Wall Mount | C9: MaxiCharger ACUltra - CSEV-AC-SP - 80A Output - Single Port Wall Mount. Includes 3 Years of Parts Only Warranty | D9: Autel | E9: 3173 | F9: 900 | G9: 250 | H9: 250 | I9: 750 | J9: 1250 | K9: 150 | L9: 450 | M9: 750 | N9: 350 | O9: 1 | P9: charger | Q9: level2 | R9: =700*1.25 -> 875 | S9: =ROUNDUP(R9*(1+$X$1),-2) -> 1000 | T9: =500*1.25 -> 625 | U9: =ROUNDUP(T9*(1+$X$1),-2) -> 700 | V9: =900*1.25 -> 1125 | W9: =ROUNDUP(V9*(1+$X$1),-2) -> 1300
A10: csev-ac-sp-32a-pedestal | B10: MaxiCharger ACUltra - CSEV-AC-SP - 32A Output - Single Port Pedestal with CMS | C10: MaxiCharger ACUltra - CSEV-AC-SP - 32A Output - Single Port Pedestal with CMS. Includes 3 Years of Parts Only Warranty | D10: Autel | E10: 4423 | F10: 1580 | G10: 250 | H10: 250 | I10: 750 | J10: 1250 | K10: 150 | L10: 450 | M10: 750 | N10: 350 | O10: 1 | P10: charger | Q10: level2 | R10: =700*1.25 -> 875 | S10: =ROUNDUP(R10*(1+$X$1),-2) -> 1000 | T10: =500*1.25 -> 625 | U10: =ROUNDUP(T10*(1+$X$1),-2) -> 700 | V10: =900*1.25 -> 1125 | W10: =ROUNDUP(V10*(1+$X$1),-2) -> 1300
A11: csev-ac-sp-32a-wall | B11: MaxiCharger ACUltra - CSEV-AC-SP - 32A Output - Single Port Wall Mount | C11: MaxiCharger ACUltra - CSEV-AC-SP - 32A Output - Single Port Wall Mount. Includes 3 Years of Parts Only Warranty | D11: Autel | E11: 3173 | F11: 900 | G11: 250 | H11: 250 | I11: 750 | J11: 1250 | K11: 150 | L11: 450 | M11: 750 | N11: 350 | O11: 1 | P11: charger | Q11: level2 | R11: =700*1.25 -> 875 | S11: =ROUNDUP(R11*(1+$X$1),-2) -> 1000 | T11: =500*1.25 -> 625 | U11: =ROUNDUP(T11*(1+$X$1),-2) -> 700 | V11: =900*1.25 -> 1125 | W11: =ROUNDUP(V11*(1+$X$1),-2) -> 1300
A12: csev-acpro-sp-50a-wall | B12: MaxiCharger ACPro - CSEV-AC-SP - 50A Output - Single Port Wall Mount | C12: MaxiCharger ACPro - CSEV-AC-SP - 50A Output - Single Port Wall Mount. Includes 3 Years of Parts Only Warranty | D12: Autel | E12: 2500 | F12: 750 | G12: 250 | H12: 250 | I12: 750 | J12: 1250 | K12: 150 | L12: 450 | M12: 750 | N12: 175 | O12: 1 | P12: charger | Q12: level2 | R12: =700*1.25 -> 875 | S12: =ROUNDUP(R12*(1+$X$1),-2) -> 1000 | T12: =500*1.25 -> 625 | U12: =ROUNDUP(T12*(1+$X$1),-2) -> 700 | V12: =900*1.25 -> 1125 | W12: =ROUNDUP(V12*(1+$X$1),-2) -> 1300
A13: csev-ac-dp-48a | B13: MaxiCharger ACUltra - CSEV-AC-DP - 48A Output - Dual Port Pedestal with CMS | C13: MaxiCharger ACUltra - CSEV-AC-DP - 48A Output - Dual Port Pedestal with CMS. Includes 3 Years of Parts Only Warranty | D13: Autel | E13: 5323 | F13: 2750 | G13: 500 | H13: 500 | I13: 1500 | J13: 2500 | K13: 300 | L13: 900 | M13: 1500 | N13: 350 | O13: 2 | P13: charger | Q13: level2 | R13: =1400*1.25 -> 1750 | S13: =R13*(1+$X$1) -> 1925 | T13: =1000*1.25 -> 1250 | U13: =T13*(1+$X$1) -> 1375 | V13: =1800*1.25 -> 2250 | W13: =V13*(1+$X$1) -> 2475
A14: csev-ac-dp-40a | B14: MaxiCharger ACUltra - CSEV-AC-DP - 40A Output - Dual Port Pedestal with CMS | C14: MaxiCharger ACUltra - CSEV-AC-DP - 40A Output - Dual Port Pedestal with CMS. Includes 3 Years of Parts Only Warranty | D14: Autel | E14: 5323 | F14: 2750 | G14: 500 | H14: 500 | I14: 1500 | J14: 2500 | K14: 300 | L14: 900 | M14: 1500 | N14: 350 | O14: 2 | P14: charger | Q14: level2 | R14: =1400*1.25 -> 1750 | S14: =R14*(1+$X$1) -> 1925 | T14: =1000*1.25 -> 1250 | U14: =T14*(1+$X$1) -> 1375 | V14: =1800*1.25 -> 2250 | W14: =V14*(1+$X$1) -> 2475
A15: csev-ac-dp-80a | B15: MaxiCharger ACUltra - CSEV-AC-DP - 80A Output - Dual Port Pedestal with CMS | C15: MaxiCharger ACUltra - CSEV-AC-DP - 80A Output - Dual Port Pedestal with CMS. Includes 3 Years of Parts Only Warranty | D15: Autel | E15: 5323 | F15: 2750 | G15: 500 | H15: 500 | I15: 1500 | J15: 2500 | K15: 300 | L15: 900 | M15: 1500 | N15: 350 | O15: 2 | P15: charger | Q15: level2 | R15: =1400*1.25 -> 1750 | S15: =R15*(1+$X$1) -> 1925 | T15: =1000*1.25 -> 1250 | U15: =T15*(1+$X$1) -> 1375 | V15: =1800*1.25 -> 2250 | W15: =V15*(1+$X$1) -> 2475
A16: csev-ac-dp-32a | B16: MaxiCharger ACUltra - CSEV-AC-DP - 32A Output - Dual Port Pedestal with CMS | C16: MaxiCharger ACUltra - CSEV-AC-DP - 32A Output - Dual Port Pedestal with CMS. Includes 3 Years of Parts Only Warranty | D16: Autel | E16: 5323 | F16: 2750 | G16: 500 | H16: 500 | I16: 1500 | J16: 2500 | K16: 300 | L16: 900 | M16: 1500 | N16: 350 | O16: 2 | P16: charger | Q16: level2 | R16: =1400*1.25 -> 1750 | S16: =R16*(1+$X$1) -> 1925 | T16: =1000*1.25 -> 1250 | U16: =T16*(1+$X$1) -> 1375 | V16: =1800*1.25 -> 2250 | W16: =V16*(1+$X$1) -> 2475
B17: MaxiCharger ACElite
A19: csev-dcfc-60-ccs | B19: CSEV MaxiCharger 60kW DC Fast - CCS/CCS - POS & CMS & Boost Cables | C19: CSEV MaxiCharger 60kW DC Fast - CCS/CCS - POS & CMS & Boost Cables. Includes 2 Years of Parts Only Warranty | D19: Autel | E19: 48096 | F19: 36072 | G19: 680 | H19: 680 | I19: 2040 | J19: 3400 | K19: 480 | L19: 1440 | M19: 2400 | N19: 1250 | O19: 2 | P19: charger | Q19: dcfc | R19: 7700 | S19: =R19*(1+$X$1) -> 8470 | T19: 3100 | U19: =T19*(1+$X$1) -> 3410 | V19: =((R19-T19)*2)+T19 -> 12300 | W19: =V19*(1+$X$1) -> 13530
A20: csev-dcfc-120-ccs | B20: CSEV MaxiCharger 120kW DC Fast - CCS/CCS - POS & CMS & Boost Cables | C20: CSEV MaxiCharger 120kW DC Fast - CCS/CCS - POS & CMS & Boost Cables. Includes 2 Years of Parts Only Warranty | D20: Autel | E20: 52128 | F20: 39096 | G20: 680 | H20: 680 | I20: 2040 | J20: 3400 | K20: 480 | L20: 1440 | M20: 2400 | N20: 1250 | O20: 2 | P20: charger | Q20: dcfc | R20: 10000 | S20: =R20*(1+$X$1) -> 11000 | T20: 4000 | U20: =T20*(1+$X$1) -> 4400 | V20: =((R20-T20)*2)+T20 -> 16000 | W20: =V20*(1+$X$1) -> 17600
A21: csev-dcfc-180-ccs | B21: CSEV MaxiCharger 180kW DC Fast - CCS/CCS - POS & CMS & Boost Cables | C21: CSEV MaxiCharger 180kW DC Fast - CCS/CCS - POS & CMS & Boost Cables. Includes 2 Years of Parts Only Warranty | D21: Autel | E21: 64368 | F21: 48276 | G21: 680 | H21: 680 | I21: 2040 | J21: 3400 | K21: 480 | L21: 1440 | M21: 2400 | N21: 1250 | O21: 2 | P21: charger | Q21: dcfc | R21: 12200 | S21: =R21*(1+$X$1) -> 13420 | T21: 4900 | U21: =T21*(1+$X$1) -> 5390 | V21: =((R21-T21)*2)+T21 -> 19500 | W21: =V21*(1+$X$1) -> 21450
A22: csev-dcfc-240-ccs | B22: CSEV MaxiCharger 240kW DC Fast - CCS/CCS - POS & CMS & Boost Cables | C22: CSEV MaxiCharger 240kW DC Fast - CCS/CCS - POS & CMS & Boost Cables. Includes 2 Years of Parts Only Warranty | D22: Autel | E22: 79200 | F22: 59400 | G22: 680 | H22: 680 | I22: 2040 | J22: 3400 | K22: 480 | L22: 1440 | M22: 2400 | N22: 1250 | O22: 2 | P22: charger | Q22: dcfc | R22: 14500 | S22: =R22*(1+$X$1) -> 15950 | T22: 5800 | U22: =T22*(1+$X$1) -> 6380 | V22: =((R22-T22)*2)+T22 -> 23200 | W22: =V22*(1+$X$1) -> 25520
A23: csev-dcfc-60-nacs | B23: CSEV MaxiCharger 60kW DC Fast - CCS/NACS - POS & CMS & Boost Cables | C23: CSEV MaxiCharger 60kW DC Fast - CCS/NACS - POS & CMS & Boost Cables. Includes 2 Years of Parts Only Warranty | D23: Autel | E23: 48096 | F23: 36072 | G23: 680 | H23: 680 | I23: 2040 | J23: 3400 | K23: 480 | L23: 1440 | M23: 2400 | N23: 1250 | O23: 2 | P23: charger | Q23: dcfc | R23: 7700 | S23: =R23*(1+$X$1) -> 8470 | T23: 3100 | U23: =T23*(1+$X$1) -> 3410 | V23: =((R23-T23)*2)+T23 -> 12300 | W23: =V23*(1+$X$1) -> 13530
A24: csev-dcfc-120-nacs | B24: CSEV MaxiCharger 120kW DC Fast - CCS/NACS - POS & CMS & Boost Cables | C24: CSEV MaxiCharger 120kW DC Fast - CCS/NACS - POS & CMS & Boost Cables. Includes 2 Years of Parts Only Warranty | D24: Autel | E24: 52128 | F24: 39096 | G24: 680 | H24: 680 | I24: 2040 | J24: 3400 | K24: 480 | L24: 1440 | M24: 2400 | N24: 1250 | O24: 2 | P24: charger | Q24: dcfc | R24: 10000 | S24: =R24*(1+$X$1) -> 11000 | T24: 4000 | U24: =T24*(1+$X$1) -> 4400 | V24: =((R24-T24)*2)+T24 -> 16000 | W24: =V24*(1+$X$1) -> 17600
A25: csev-dcfc-180-nacs | B25: CSEV MaxiCharger 180kW DC Fast - CCS/NACS - POS & CMS & Boost Cables | C25: CSEV MaxiCharger 180kW DC Fast - CCS/NACS - POS & CMS & Boost Cables. Includes 2 Years of Parts Only Warranty | D25: Autel | E25: 64368 | F25: 48276 | G25: 680 | H25: 680 | I25: 2040 | J25: 3400 | K25: 480 | L25: 1440 | M25: 2400 | N25: 1250 | O25: 2 | P25: charger | Q25: dcfc | R25: 12200 | S25: =R25*(1+$X$1) -> 13420 | T25: 4900 | U25: =T25*(1+$X$1) -> 5390 | V25: =((R25-T25)*2)+T25 -> 19500 | W25: =V25*(1+$X$1) -> 21450
A26: csev-dcfc-240-nacs | B26: CSEV MaxiCharger 240kW DC Fast - CCS/NACS - POS & CMS & Boost Cables | C26: CSEV MaxiCharger 240kW DC Fast - CCS/NACS - POS & CMS & Boost Cables. Includes 2 Years of Parts Only Warranty | D26: Autel | E26: 79200 | F26: 59400 | G26: 680 | H26: 680 | I26: 2040 | J26: 3400 | K26: 480 | L26: 1440 | M26: 2400 | N26: 1250 | O26: 2 | P26: charger | Q26: dcfc | R26: 14500 | S26: =R26*(1+$X$1) -> 15950 | T26: 5800 | U26: =T26*(1+$X$1) -> 6380 | V26: =((R26-T26)*2)+T26 -> 23200 | W26: =V26*(1+$X$1) -> 25520
A27: csev-dchp-320-set2-ccs-ccs | B27: Set of 2 - 320kW - CSEV DCHP 320kW - CCS/CCS - POS & CMS & Boost Cables | C27: Set of 2 - CSEV DCHP 320kW - CCS/CCS - POS & CMS & Boost Cables. Includes 2 Years of Parts Only Warranty | D27: Autel | E27: 146667 | F27: 110000 | G27: 680 | H27: 680 | I27: 2040 | J27: 3400 | K27: 480 | L27: 1440 | M27: 2400 | N27: 1250 | O27: 2 | P27: charger | Q27: dcfc | R27: 25000 | S27: =R27*(1+$X$1) -> 27500 | T27: 20000 | U27: =T27*(1+$X$1) -> 22000 | V27: =((R27-T27)*2)+T27 -> 30000 | W27: =V27*(1+$X$1) -> 33000
A28: csev-dchp-320-set2-ccs-nacs | B28: Set of 2 - 320kW - CSEV DCHP 320kW - CCS/NACS - POS & CMS & Boost Cables | C28: Set of 2 - CSEV DCHP 320kW - CCS/NACS - POS & CMS & Boost Cables. Includes 2 Years of Parts Only Warranty | D28: Autel | E28: 146667 | F28: 110000 | G28: 680 | H28: 680 | I28: 2040 | J28: 3400 | K28: 480 | L28: 1440 | M28: 2400 | N28: 1250 | O28: 2 | P28: charger | Q28: dcfc | R28: 25000 | S28: =R28*(1+$X$1) -> 27500 | T28: 20000 | U28: =T28*(1+$X$1) -> 22000 | V28: =((R28-T28)*2)+T28 -> 30000 | W28: =V28*(1+$X$1) -> 33000
A29: csev-dchp-320-set2-nacs-nacs | B29: Set of 2 - 320kW - CSEV DCHP 320kW - NACS/NACS - POS & CMS & Boost Cables | C29: Set of 2 - CSEV DCHP 320kW - NACS/NACS - POS & CMS & Boost Cables. Includes 2 Years of Parts Only Warranty | D29: Autel | E29: 146667 | F29: 110000 | G29: 680 | H29: 680 | I29: 2040 | J29: 3400 | K29: 480 | L29: 1440 | M29: 2400 | N29: 1250 | O29: 2 | P29: charger | Q29: dcfc | R29: 25000 | S29: =R29*(1+$X$1) -> 27500 | T29: 20000 | U29: =T29*(1+$X$1) -> 22000 | V29: =((R29-T29)*2)+T29 -> 30000 | W29: =V29*(1+$X$1) -> 33000
A30: csev-dchp-640-set4-ccs-nacs | B30: Set of 4 - 640kW - CSEV DCHP 320kW - CCS/CCS & NACS/NACS - POS & CMS & Boost Cables | C30: Set of 4 - CSEV DCHP 320kW - CCS/CCS & NACS/NACS - POS & CMS & Boost Cables. Includes 2 Years of Parts Only Warranty | D30: Autel | E30: 196933 | F30: 147700 | G30: 1360 | H30: 1360 | I30: 4080 | J30: 6800 | K30: 960 | L30: 2880 | M30: 4800 | N30: 1250 | O30: 4 | P30: charger | Q30: dcfc | R30: =R27*2 -> 50000 | S30: =R30*(1+$X$1) -> 55000 | T30: =T27*2 -> 40000 | U30: =T30*(1+$X$1) -> 44000 | V30: =V27*2 -> 60000 | W30: =V30*(1+$X$1) -> 66000
A31: csev-dchp-640-set4-ccs-ccs | B31: Set of 4 - 640kW - CSEV DCHP 320kW - CCS/CCS & CCS/CCS - POS & CMS & Boost Cables | C31: Set of 4 - CSEV DCHP 320kW - CCS/CCS & CCS/CCS - POS & CMS & Boost Cables. Includes 2 Years of Parts Only Warranty | D31: Autel | E31: 196933 | F31: 147700 | G31: 1360 | H31: 1360 | I31: 4080 | J31: 6800 | K31: 960 | L31: 2880 | M31: 4800 | N31: 1250 | O31: 4 | P31: charger | Q31: dcfc | R31: =R28*2 -> 50000 | S31: =R31*(1+$X$1) -> 55000 | T31: =T28*2 -> 40000 | U31: =T31*(1+$X$1) -> 44000 | V31: =V28*2 -> 60000 | W31: =V31*(1+$X$1) -> 66000
A32: csev-dchp-640-set4-nacs-nacs | B32: Set of 4 - 640kW - CSEV DCHP 320kW - NACS/NACS & NACS/NACS - POS & CMS & Boost Cables | C32: Set of 4 - CSEV DCHP 320kW - NACS/NACS & NACS/NACS - POS & CMS & Boost Cables. Includes 2 Years of Parts Only Warranty | D32: Autel | E32: 196933 | F32: 147700 | G32: 1360 | H32: 1360 | I32: 4080 | J32: 6800 | K32: 960 | L32: 2880 | M32: 4800 | N32: 1250 | O32: 4 | P32: charger | Q32: dcfc | R32: =R29*2 -> 50000 | S32: =R32*(1+$X$1) -> 55000 | T32: =T29*2 -> 40000 | U32: =T32*(1+$X$1) -> 44000 | V32: =V29*2 -> 60000 | W32: =V32*(1+$X$1) -> 66000

Sheet EVSE Products-MA
A1: ID | B1: Name | C1: Description | D1: Manufacturer | E1: Unit Price ($) | F1: CSEV Cost ($) | G1: Annual Network Plan ($) | H1: Network Plan 1yr ($) | I1: Network Plan 3yr ($) | J1: Network Plan 5yr ($) | K1: Network Cost 1yr ($) | L1: Network Cost 3yr ($) | M1: Network Cost 5yr ($) | N1: Shipping ($) | O1: Number of Plugs | P1: Category | Q1: Charging Level | R1: calc1-ignore | S1: Warranty: 5-Yr Parts ONLY ($) | T1: calc2-ignore | U1: Warranty: 3-Yr FULL P&L ($) | V1: calc3-ignore | W1: Warranty: 5-Yr FULL P&L ($) | X1: 0.1
A2: csev-acpro-pedestal | B2: MaxiCharger ACPro - Pedestal | C2: Pedestal mount accessory for MaxiCharger ACPro | D2: Autel | E2: =ROUND('EVSE Products-NY'!E2*(1+'EVSE Products-MA'!$A$53),0) -> 1100 | F2: 500 | G2: 0 | H2: 0 | I2: 0 | J2: 0 | K2: 0 | L2: 0 | M2: 0 | N2: 0 | O2: 0 | P2: accessory | Q2: level2 | R2: 1000 | S2: =R2*(1+$X$1) -> 1100 | T2: 750 | U2: =T2*(1+$X$1) -> 825 | V2: 1250 | W2: =V2*(1+$X$1) -> 1375
A3: csev-acultra-cable-mgmt | B3: MaxiCharger ACUltra - Cable Management | C3: Cable management accessory for MaxiCharger ACUltra | D3: Autel | E3: =ROUND('EVSE Products-NY'!E3*(1+'EVSE Products-MA'!$A$53),0) -> 1100 | F3: 500 | G3: 0 | H3: 0 | I3: 0 | J3: 0 | K3: 0 | L3: 0 | M3: 0 | N3: 0 | O3: 0 | P3: accessory | Q3: level2 | R3: 1000 | S3: =R3*(1+$X$1) -> 1100 | T3: 750 | U3: =T3*(1+$X$1) -> 825 | V3: 1250 | W3: =V3*(1+$X$1) -> 1375
A4: csev-ac-sp-48a-pedestal | B4: MaxiCharger ACUltra - CSEV-AC-SP - 48A Output - Single Port Pedestal with CMS | C4: MaxiCharger ACUltra - CSEV-AC-SP - 48A Output - Single Port Pedestal with CMS. Includes 3 Years of Parts Only Warranty | D4: Autel | E4: =ROUND('EVSE Products-NY'!E4*(1+'EVSE Products-MA'!$A$53),0) -> 4865 | F4: 1580 | G4: 250 | H4: 250 | I4: 750 | J4: 1250 | K4: 150 | L4: 450 | M4: 750 | N4: 350 | O4: 1 | P4: charger | Q4: level2 | R4: =700*1.25 -> 875 | S4: =ROUNDUP(R4*(1+$X$1),-2) -> 1000 | T4: =500*1.25 -> 625 | U4: =ROUNDUP(T4*(1+$X$1),-2) -> 700 | V4: =900*1.25 -> 1125 | W4: =ROUNDUP(V4*(1+$X$1),-2) -> 1300
A5: csev-ac-sp-48a-wall | B5: MaxiCharger ACUltra - CSEV-AC-SP - 48A Output - Single Port Wall Mount | C5: MaxiCharger ACUltra - CSEV-AC-SP - 48A Output - Single Port Wall Mount. Includes 3 Years of Parts Only Warranty | D5: Autel | E5: =ROUND('EVSE Products-NY'!E5*(1+'EVSE Products-MA'!$A$53),0) -> 3490 | F5: 900 | G5: 250 | H5: 250 | I5: 750 | J5: 1250 | K5: 150 | L5: 450 | M5: 750 | N5: 350 | O5: 1 | P5: charger | Q5: level2 | R5: =700*1.25 -> 875 | S5: =ROUNDUP(R5*(1+$X$1),-2) -> 1000 | T5: =500*1.25 -> 625 | U5: =ROUNDUP(T5*(1+$X$1),-2) -> 700 | V5: =900*1.25 -> 1125 | W5: =ROUNDUP(V5*(1+$X$1),-2) -> 1300
A6: csev-ac-sp-40a-pedestal | B6: MaxiCharger ACUltra - CSEV-AC-SP - 40A Output - Single Port Pedestal with CMS | C6: MaxiCharger ACUltra - CSEV-AC-SP - 40A Output - Single Port Pedestal with CMS. Includes 3 Years of Parts Only Warranty | D6: Autel | E6: =ROUND('EVSE Products-NY'!E6*(1+'EVSE Products-MA'!$A$53),0) -> 4865 | F6: 1580 | G6: 250 | H6: 250 | I6: 750 | J6: 1250 | K6: 150 | L6: 450 | M6: 750 | N6: 350 | O6: 1 | P6: charger | Q6: level2 | R6: =700*1.25 -> 875 | S6: =ROUNDUP(R6*(1+$X$1),-2) -> 1000 | T6: =500*1.25 -> 625 | U6: =ROUNDUP(T6*(1+$X$1),-2) -> 700 | V6: =900*1.25 -> 1125 | W6: =ROUNDUP(V6*(1+$X$1),-2) -> 1300
A7: csev-ac-sp-40a-wall | B7: MaxiCharger ACUltra - CSEV-AC-SP - 40A Output - Single Port Wall Mount | C7: MaxiCharger ACUltra - CSEV-AC-SP - 40A Output - Single Port Wall Mount. Includes 3 Years of Parts Only Warranty | D7: Autel | E7: =ROUND('EVSE Products-NY'!E7*(1+'EVSE Products-MA'!$A$53),0) -> 3490 | F7: 900 | G7: 250 | H7: 250 | I7: 750 | J7: 1250 | K7: 150 | L7: 450 | M7: 750 | N7: 350 | O7: 1 | P7: charger | Q7: level2 | R7: =700*1.25 -> 875 | S7: =ROUNDUP(R7*(1+$X$1),-2) -> 1000 | T7: =500*1.25 -> 625 | U7: =ROUNDUP(T7*(1+$X$1),-2) -> 700 | V7: =900*1.25 -> 1125 | W7: =ROUNDUP(V7*(1+$X$1),-2) -> 1300
A8: csev-ac-sp-80a-pedestal | B8: MaxiCharger ACUltra - CSEV-AC-SP - 80A Output - Single Port Pedestal with CMS | C8: MaxiCharger ACUltra - CSEV-AC-SP - 80A Output - Single Port Pedestal with CMS. Includes 3 Years of Parts Only Warranty | D8: Autel | E8: =ROUND('EVSE Products-NY'!E8*(1+'EVSE Products-MA'!$A$53),0) -> 4865 | F8: 1580 | G8: 250 | H8: 250 | I8: 750 | J8: 1250 | K8: 150 | L8: 450 | M8: 750 | N8: 350 | O8: 1 | P8: charger | Q8: level2 | R8: =700*1.25 -> 875 | S8: =ROUNDUP(R8*(1+$X$1),-2) -> 1000 | T8: =500*1.25 -> 625 | U8: =ROUNDUP(T8*(1+$X$1),-2) -> 700 | V8: =900*1.25 -> 1125 | W8: =ROUNDUP(V8*(1+$X$1),-2) -> 1300
A9: csev-ac-sp-80a-wall | B9: MaxiCharger ACUltra - CSEV-AC-SP - 80A Output - Single Port Wall Mount | C9: MaxiCharger ACUltra - CSEV-AC-SP - 80A Output - Single Port Wall Mount. Includes 3 Years of Parts Only Warranty | D9: Autel | E9: =ROUND('EVSE Products-NY'!E9*(1+'EVSE Products-MA'!$A$53),0) -> 3490 | F9: 900 | G9: 250 | H9: 250 | I9: 750 | J9: 1250 | K9: 150 | L9: 450 | M9: 750 | N9: 350 | O9: 1 | P9: charger | Q9: level2 | R9: =700*1.25 -> 875 | S9: =ROUNDUP(R9*(1+$X$1),-2) -> 1000 | T9: =500*1.25 -> 625 | U9: =ROUNDUP(T9*(1+$X$1),-2) -> 700 | V9: =900*1.25 -> 1125 | W9: =ROUNDUP(V9*(1+$X$1),-2) -> 1300
A10: csev-ac-sp-32a-pedestal | B10: MaxiCharger ACUltra - CSEV-AC-SP - 32A Output - Single Port Pedestal with CMS | C10: MaxiCharger ACUltra - CSEV-AC-SP - 32A Output - Single Port Pedestal with CMS. Includes 3 Years of Parts Only Warranty | D10: Autel | E10: =ROUND('EVSE Products-NY'!E10*(1+'EVSE Products-MA'!$A$53),0) -> 4865 | F10: 1580 | G10: 250 | H10: 250 | I10: 750 | J10: 1250 | K10: 150 | L10: 450 | M10: 750 | N10: 350 | O10: 1 | P10: charger | Q10: level2 | R10: =700*1.25 -> 875 | S10: =ROUNDUP(R10*(1+$X$1),-2) -> 1000 | T10: =500*1.25 -> 625 | U10: =ROUNDUP(T10*(1+$X$1),-2) -> 700 | V10: =900*1.25 -> 1125 | W10: =ROUNDUP(V10*(1+$X$1),-2) -> 1300
A11: csev-ac-sp-32a-wall | B11: MaxiCharger ACUltra - CSEV-AC-SP - 32A Output - Single Port Wall Mount | C11: MaxiCharger ACUltra - CSEV-AC-SP - 32A Output - Single Port Wall Mount. Includes 3 Years of Parts Only Warranty | D11: Autel | E11: =ROUND('EVSE Products-NY'!E11*(1+'EVSE Products-MA'!$A$53),0) -> 3490 | F11: 900 | G11: 250 | H11: 250 | I11: 750 | J11: 1250 | K11: 150 | L11: 450 | M11: 750 | N11: 350 | O11: 1 | P11: charger | Q11: level2 | R11: =700*1.25 -> 875 | S11: =ROUNDUP(R11*(1+$X$1),-2) -> 1000 | T11: =500*1.25 -> 625 | U11: =ROUNDUP(T11*(1+$X$1),-2) -> 700 | V11: =900*1.25 -> 1125 | W11: =ROUNDUP(V11*(1+$X$1),-2) -> 1300
A12: csev-acpro-sp-50a-wall | B12: MaxiCharger ACPro - CSEV-AC-SP - 50A Output - Single Port Wall Mount | C12: MaxiCharger ACPro - CSEV-AC-SP - 50A Output - Single Port Wall Mount. Includes 3 Years of Parts Only Warranty | D12: Autel | E12: =ROUND('EVSE Products-NY'!E12*(1+'EVSE Products-MA'!$A$53),0) -> 2750 | F12: 750 | G12: 250 | H12: 250 | I12: 750 | J12: 1250 | K12: 150 | L12: 450 | M12: 750 | N12: 175 | O12: 1 | P12: charger | Q12: level2 | R12: =700*1.25 -> 875 | S12: =ROUNDUP(R12*(1+$X$1),-2) -> 1000 | T12: =500*1.25 -> 625 | U12: =ROUNDUP(T12*(1+$X$1),-2) -> 700 | V12: =900*1.25 -> 1125 | W12: =ROUNDUP(V12*(1+$X$1),-2) -> 1300
A13: csev-ac-dp-48a | B13: MaxiCharger ACUltra - CSEV-AC-DP - 48A Output - Dual Port Pedestal with CMS | C13: MaxiCharger ACUltra - CSEV-AC-DP - 48A Output - Dual Port Pedestal with CMS. Includes 3 Years of Parts Only Warranty | D13: Autel | E13: =ROUND('EVSE Products-NY'!E13*(1+'EVSE Products-MA'!$A$53),0) -> 5855 | F13: 2750 | G13: 500 | H13: 500 | I13: 1500 | J13: 2500 | K13: 300 | L13: 900 | M13: 1500 | N13: 350 | O13: 2 | P13: charger | Q13: level2 | R13: =1400*1.25 -> 1750 | S13: =R13*(1+$X$1) -> 1925 | T13: =1000*1.25 -> 1250 | U13: =T13*(1+$X$1) -> 1375 | V13: =1800*1.25 -> 2250 | W13: =V13*(1+$X$1) -> 2475
A14: csev-ac-dp-40a | B14: MaxiCharger ACUltra - CSEV-AC-DP - 40A Output - Dual Port Pedestal with CMS | C14: MaxiCharger ACUltra - CSEV-AC-DP - 40A Output - Dual Port Pedestal with CMS. Includes 3 Years of Parts Only Warranty | D14: Autel | E14: =ROUND('EVSE Products-NY'!E14*(1+'EVSE Products-MA'!$A$53),0) -> 5855 | F14: 2750 | G14: 500 | H14: 500 | I14: 1500 | J14: 2500 | K14: 300 | L14: 900 | M14: 1500 | N14: 350 | O14: 2 | P14: charger | Q14: level2 | R14: =1400*1.25 -> 1750 | S14: =R14*(1+$X$1) -> 1925 | T14: =1000*1.25 -> 1250 | U14: =T14*(1+$X$1) -> 1375 | V14: =1800*1.25 -> 2250 | W14: =V14*(1+$X$1) -> 2475
A15: csev-ac-dp-80a | B15: MaxiCharger ACUltra - CSEV-AC-DP - 80A Output - Dual Port Pedestal with CMS | C15: MaxiCharger ACUltra - CSEV-AC-DP - 80A Output - Dual Port Pedestal with CMS. Includes 3 Years of Parts Only Warranty | D15: Autel | E15: =ROUND('EVSE Products-NY'!E15*(1+'EVSE Products-MA'!$A$53),0) -> 5855 | F15: 2750 | G15: 500 | H15: 500 | I15: 1500 | J15: 2500 | K15: 300 | L15: 900 | M15: 1500 | N15: 350 | O15: 2 | P15: charger | Q15: level2 | R15: =1400*1.25 -> 1750 | S15: =R15*(1+$X$1) -> 1925 | T15: =1000*1.25 -> 1250 | U15: =T15*(1+$X$1) -> 1375 | V15: =1800*1.25 -> 2250 | W15: =V15*(1+$X$1) -> 2475
A16: csev-ac-dp-32a | B16: MaxiCharger ACUltra - CSEV-AC-DP - 32A Output - Dual Port Pedestal with CMS | C16: MaxiCharger ACUltra - CSEV-AC-DP - 32A Output - Dual Port Pedestal with CMS. Includes 3 Years of Parts Only Warranty | D16: Autel | E16: =ROUND('EVSE Products-NY'!E16*(1+'EVSE Products-MA'!$A$53),0) -> 5855 | F16: 2750 | G16: 500 | H16: 500 | I16: 1500 | J16: 2500 | K16: 300 | L16: 900 | M16: 1500 | N16: 350 | O16: 2 | P16: charger | Q16: level2 | R16: =1400*1.25 -> 1750 | S16: =R16*(1+$X$1) -> 1925 | T16: =1000*1.25 -> 1250 | U16: =T16*(1+$X$1) -> 1375 | V16: =1800*1.25 -> 2250 | W16: =V16*(1+$X$1) -> 2475
A17: csev-dcfc-60-ccs | B17: CSEV MaxiCharger 60kW DC Fast - CCS/CCS - POS & CMS & Boost Cables | C17: CSEV MaxiCharger 60kW DC Fast - CCS/CCS - POS & CMS & Boost Cables. Includes 2 Years of Parts Only Warranty | D17: Autel | E17: =ROUND('EVSE Products-NY'!E19*(1+'EVSE Products-MA'!$A$53),0) -> 52906 | F17: 36072 | G17: 680 | H17: 680 | I17: 2040 | J17: 3400 | K17: 480 | L17: 1440 | M17: 2400 | N17: 1250 | O17: 2 | P17: charger | Q17: dcfc | R17: 7700 | S17: =R17*(1+$X$1) -> 8470 | T17: 3100 | U17: =T17*(1+$X$1) -> 3410 | V17: =((R17-T17)*2)+T17 -> 12300 | W17: =V17*(1+$X$1) -> 13530
A18: csev-dcfc-120-ccs | B18: CSEV MaxiCharger 120kW DC Fast - CCS/CCS - POS & CMS & Boost Cables | C18: CSEV MaxiCharger 120kW DC Fast - CCS/CCS - POS & CMS & Boost Cables. Includes 2 Years of Parts Only Warranty | D18: Autel | E18: =ROUND('EVSE Products-NY'!E20*(1+'EVSE Products-MA'!$A$53),0) -> 57341 | F18: 39096 | G18: 680 | H18: 680 | I18: 2040 | J18: 3400 | K18: 480 | L18: 1440 | M18: 2400 | N18: 1250 | O18: 2 | P18: charger | Q18: dcfc | R18: 10000 | S18: =R18*(1+$X$1) -> 11000 | T18: 4000 | U18: =T18*(1+$X$1) -> 4400 | V18: =((R18-T18)*2)+T18 -> 16000 | W18: =V18*(1+$X$1) -> 17600
A19: csev-dcfc-180-ccs | B19: CSEV MaxiCharger 180kW DC Fast - CCS/CCS - POS & CMS & Boost Cables | C19: CSEV MaxiCharger 180kW DC Fast - CCS/CCS - POS & CMS & Boost Cables. Includes 2 Years of Parts Only Warranty | D19: Autel | E19: =ROUND('EVSE Products-NY'!E21*(1+'EVSE Products-MA'!$A$53),0) -> 70805 | F19: 48276 | G19: 680 | H19: 680 | I19: 2040 | J19: 3400 | K19: 480 | L19: 1440 | M19: 2400 | N19: 1250 | O19: 2 | P19: charger | Q19: dcfc | R19: 12200 | S19: =R19*(1+$X$1) -> 13420 | T19: 4900 | U19: =T19*(1+$X$1) -> 5390 | V19: =((R19-T19)*2)+T19 -> 19500 | W19: =V19*(1+$X$1) -> 21450
A20: csev-dcfc-240-ccs | B20: CSEV MaxiCharger 240kW DC Fast - CCS/CCS - POS & CMS & Boost Cables | C20: CSEV MaxiCharger 240kW DC Fast - CCS/CCS - POS & CMS & Boost Cables. Includes 2 Years of Parts Only Warranty | D20: Autel | E20: =ROUND('EVSE Products-NY'!E22*(1+'EVSE Products-MA'!$A$53),0) -> 87120 | F20: 59400 | G20: 680 | H20: 680 | I20: 2040 | J20: 3400 | K20: 480 | L20: 1440 | M20: 2400 | N20: 1250 | O20: 2 | P20: charger | Q20: dcfc | R20: 14500 | S20: =R20*(1+$X$1) -> 15950 | T20: 5800 | U20: =T20*(1+$X$1) -> 6380 | V20: =((R20-T20)*2)+T20 -> 23200 | W20: =V20*(1+$X$1) -> 25520
A21: csev-dcfc-60-nacs | B21: CSEV MaxiCharger 60kW DC Fast - CCS/NACS - POS & CMS & Boost Cables | C21: CSEV MaxiCharger 60kW DC Fast - CCS/NACS - POS & CMS & Boost Cables. Includes 2 Years of Parts Only Warranty | D21: Autel | E21: =ROUND('EVSE Products-NY'!E23*(1+'EVSE Products-MA'!$A$53),0) -> 52906 | F21: 36072 | G21: 680 | H21: 680 | I21: 2040 | J21: 3400 | K21: 480 | L21: 1440 | M21: 2400 | N21: 1250 | O21: 2 | P21: charger | Q21: dcfc | R21: 7700 | S21: =R21*(1+$X$1) -> 8470 | T21: 3100 | U21: =T21*(1+$X$1) -> 3410 | V21: =((R21-T21)*2)+T21 -> 12300 | W21: =V21*(1+$X$1) -> 13530
A22: csev-dcfc-120-nacs | B22: CSEV MaxiCharger 120kW DC Fast - CCS/NACS - POS & CMS & Boost Cables | C22: CSEV MaxiCharger 120kW DC Fast - CCS/NACS - POS & CMS & Boost Cables. Includes 2 Years of Parts Only Warranty | D22: Autel | E22: =ROUND('EVSE Products-NY'!E24*(1+'EVSE Products-MA'!$A$53),0) -> 57341 | F22: 39096 | G22: 680 | H22: 680 | I22: 2040 | J22: 3400 | K22: 480 | L22: 1440 | M22: 2400 | N22: 1250 | O22: 2 | P22: charger | Q22: dcfc | R22: 10000 | S22: =R22*(1+$X$1) -> 11000 | T22: 4000 | U22: =T22*(1+$X$1) -> 4400 | V22: =((R22-T22)*2)+T22 -> 16000 | W22: =V22*(1+$X$1) -> 17600
A23: csev-dcfc-180-nacs | B23: CSEV MaxiCharger 180kW DC Fast - CCS/NACS - POS & CMS & Boost Cables | C23: CSEV MaxiCharger 180kW DC Fast - CCS/NACS - POS & CMS & Boost Cables. Includes 2 Years of Parts Only Warranty | D23: Autel | E23: =ROUND('EVSE Products-NY'!E25*(1+'EVSE Products-MA'!$A$53),0) -> 70805 | F23: 48276 | G23: 680 | H23: 680 | I23: 2040 | J23: 3400 | K23: 480 | L23: 1440 | M23: 2400 | N23: 1250 | O23: 2 | P23: charger | Q23: dcfc | R23: 12200 | S23: =R23*(1+$X$1) -> 13420 | T23: 4900 | U23: =T23*(1+$X$1) -> 5390 | V23: =((R23-T23)*2)+T23 -> 19500 | W23: =V23*(1+$X$1) -> 21450
A24: csev-dcfc-240-nacs | B24: CSEV MaxiCharger 240kW DC Fast - CCS/NACS - POS & CMS & Boost Cables | C24: CSEV MaxiCharger 240kW DC Fast - CCS/NACS - POS & CMS & Boost Cables. Includes 2 Years of Parts Only Warranty | D24: Autel | E24: =ROUND('EVSE Products-NY'!E26*(1+'EVSE Products-MA'!$A$53),0) -> 87120 | F24: 59400 | G24: 680 | H24: 680 | I24: 2040 | J24: 3400 | K24: 480 | L24: 1440 | M24: 2400 | N24: 1250 | O24: 2 | P24: charger | Q24: dcfc | R24: 14500 | S24: =R24*(1+$X$1) -> 15950 | T24: 5800 | U24: =T24*(1+$X$1) -> 6380 | V24: =((R24-T24)*2)+T24 -> 23200 | W24: =V24*(1+$X$1) -> 25520
A25: csev-dchp-320-set2-ccs-ccs | B25: Set of 2 - 320kW - CSEV DCHP 320kW - CCS/CCS - POS & CMS & Boost Cables | C25: Set of 2 - CSEV DCHP 320kW - CCS/CCS - POS & CMS & Boost Cables. Includes 2 Years of Parts Only Warranty | D25: Autel | E25: =ROUND('EVSE Products-NY'!E27*(1+'EVSE Products-MA'!$A$53),0) -> 161334 | F25: 110000 | G25: 680 | H25: 680 | I25: 2040 | J25: 3400 | K25: 480 | L25: 1440 | M25: 2400 | N25: 1250 | O25: 2 | P25: charger | Q25: dcfc | R25: 25000 | S25: =R25*(1+$X$1) -> 27500 | T25: 20000 | U25: =T25*(1+$X$1) -> 22000 | V25: =((R25-T25)*2)+T25 -> 30000 | W25: =V25*(1+$X$1) -> 33000
A26: csev-dchp-320-set2-ccs-nacs | B26: Set of 2 - 320kW - CSEV DCHP 320kW - CCS/NACS - POS & CMS & Boost Cables | C26: Set of 2 - CSEV DCHP 320kW - CCS/NACS - POS & CMS & Boost Cables. Includes 2 Years of Parts Only Warranty | D26: Autel | E26: =ROUND('EVSE Products-NY'!E28*(1+'EVSE Products-MA'!$A$53),0) -> 161334 | F26: 110000 | G26: 680 | H26: 680 | I26: 2040 | J26: 3400 | K26: 480 | L26: 1440 | M26: 2400 | N26: 1250 | O26: 2 | P26: charger | Q26: dcfc | R26: 25000 | S26: =R26*(1+$X$1) -> 27500 | T26: 20000 | U26: =T26*(1+$X$1) -> 22000 | V26: =((R26-T26)*2)+T26 -> 30000 | W26: =V26*(1+$X$1) -> 33000
A27: csev-dchp-320-set2-nacs-nacs | B27: Set of 2 - 320kW - CSEV DCHP 320kW - NACS/NACS - POS & CMS & Boost Cables | C27: Set of 2 - CSEV DCHP 320kW - NACS/NACS - POS & CMS & Boost Cables. Includes 2 Years of Parts Only Warranty | D27: Autel | E27: =ROUND('EVSE Products-NY'!E29*(1+'EVSE Products-MA'!$A$53),0) -> 161334 | F27: 110000 | G27: 680 | H27: 680 | I27: 2040 | J27: 3400 | K27: 480 | L27: 1440 | M27: 2400 | N27: 1250 | O27: 2 | P27: charger | Q27: dcfc | R27: 25000 | S27: =R27*(1+$X$1) -> 27500 | T27: 20000 | U27: =T27*(1+$X$1) -> 22000 | V27: =((R27-T27)*2)+T27 -> 30000 | W27: =V27*(1+$X$1) -> 33000
A28: csev-dchp-640-set4-ccs-nacs | B28: Set of 4 - 640kW - CSEV DCHP 320kW - CCS/CCS & NACS/NACS - POS & CMS & Boost Cables | C28: Set of 4 - CSEV DCHP 320kW - CCS/CCS & NACS/NACS - POS & CMS & Boost Cables. Includes 2 Years of Parts Only Warranty | D28: Autel | E28: =ROUND('EVSE Products-NY'!E30*(1+'EVSE Products-MA'!$A$53),0) -> 216626 | F28: 147700 | G28: 1360 | H28: 1360 | I28: 4080 | J28: 6800 | K28: 960 | L28: 2880 | M28: 4800 | N28: 1250 | O28: 4 | P28: charger | Q28: dcfc | R28: =R25*2 -> 50000 | S28: =R28*(1+$X$1) -> 55000 | T28: =T25*2 -> 40000 | U28: =T28*(1+$X$1) -> 44000 | V28: =V25*2 -> 60000 | W28: =V28*(1+$X$1) -> 66000
A29: csev-dchp-640-set4-ccs-ccs | B29: Set of 4 - 640kW - CSEV DCHP 320kW - CCS/CCS & CCS/CCS - POS & CMS & Boost Cables | C29: Set of 4 - CSEV DCHP 320kW - CCS/CCS & CCS/CCS - POS & CMS & Boost Cables. Includes 2 Years of Parts Only Warranty | D29: Autel | E29: =ROUND('EVSE Products-NY'!E31*(1+'EVSE Products-MA'!$A$53),0) -> 216626 | F29: 147700 | G29: 1360 | H29: 1360 | I29: 4080 | J29: 6800 | K29: 960 | L29: 2880 | M29: 4800 | N29: 1250 | O29: 4 | P29: charger | Q29: dcfc | R29: =R26*2 -> 50000 | S29: =R29*(1+$X$1) -> 55000 | T29: =T26*2 -> 40000 | U29: =T29*(1+$X$1) -> 44000 | V29: =V26*2 -> 60000 | W29: =V29*(1+$X$1) -> 66000
A30: csev-dchp-640-set4-nacs-nacs | B30: Set of 4 - 640kW - CSEV DCHP 320kW - NACS/NACS & NACS/NACS - POS & CMS & Boost Cables | C30: Set of 4 - CSEV DCHP 320kW - NACS/NACS & NACS/NACS - POS & CMS & Boost Cables. Includes 2 Years of Parts Only Warranty | D30: Autel | E30: =ROUND('EVSE Products-NY'!E32*(1+'EVSE Products-MA'!$A$53),0) -> 216626 | F30: 147700 | G30: 1360 | H30: 1360 | I30: 4080 | J30: 6800 | K30: 960 | L30: 2880 | M30: 4800 | N30: 1250 | O30: 4 | P30: charger | Q30: dcfc | R30: =R27*2 -> 50000 | S30: =R30*(1+$X$1) -> 55000 | T30: =T27*2 -> 40000 | U30: =T30*(1+$X$1) -> 44000 | V30: =V27*2 -> 60000 | W30: =V30*(1+$X$1) -> 66000
A53: 0.1
A54: Above NY Pricing

Sheet EVSE Products-NJ
A1: ID | B1: Name | C1: Description | D1: Manufacturer | E1: Unit Price ($) | F1: CSEV Cost ($) | G1: Annual Network Plan ($) | H1: Network Plan 1yr ($) | I1: Network Plan 3yr ($) | J1: Network Plan 5yr ($) | K1: Network Cost 1yr ($) | L1: Network Cost 3yr ($) | M1: Network Cost 5yr ($) | N1: Shipping ($) | O1: Number of Plugs | P1: Category | Q1: Charging Level | R1: calc1-ignore | S1: Warranty: 5-Yr Parts ONLY ($) | T1: calc2-ignore | U1: Warranty: 3-Yr FULL P&L ($) | V1: calc3-ignore | W1: Warranty: 5-Yr FULL P&L ($) | X1: 0.1
A2: csev-acpro-pedestal | B2: MaxiCharger ACPro - Pedestal | C2: Pedestal mount accessory for MaxiCharger ACPro | D2: Autel | E2: =ROUND('EVSE Products-NY'!E2*(1+$A$53),0) -> 1050 | F2: 500 | G2: 0 | H2: 0 | I2: 0 | J2: 0 | K2: 0 | L2: 0 | M2: 0 | N2: 0 | O2: 0 | P2: accessory | Q2: level2 | R2: 1000 | S2: =R2*(1+$X$1) -> 1100 | T2: 750 | U2: =T2*(1+$X$1) -> 825 | V2: 1250 | W2: =V2*(1+$X$1) -> 1375
A3: csev-acultra-cable-mgmt | B3: MaxiCharger ACUltra - Cable Management | C3: Cable management accessory for MaxiCharger ACUltra | D3: Autel | E3: =ROUND('EVSE Products-NY'!E3*(1+$A$53),0) -> 1050 | F3: 500 | G3: 0 | H3: 0 | I3: 0 | J3: 0 | K3: 0 | L3: 0 | M3: 0 | N3: 0 | O3: 0 | P3: accessory | Q3: level2 | R3: 1000 | S3: =R3*(1+$X$1) -> 1100 | T3: 750 | U3: =T3*(1+$X$1) -> 825 | V3: 1250 | W3: =V3*(1+$X$1) -> 1375
A4: csev-ac-sp-48a-pedestal | B4: MaxiCharger ACUltra - CSEV-AC-SP - 48A Output - Single Port Pedestal with CMS | C4: MaxiCharger ACUltra - CSEV-AC-SP - 48A Output - Single Port Pedestal with CMS. Includes 3 Years of Parts Only Warranty | D4: Autel | E4: =ROUND('EVSE Products-NY'!E4*(1+$A$53),0) -> 4644 | F4: 1580 | G4: 250 | H4: 250 | I4: 750 | J4: 1250 | K4: 150 | L4: 450 | M4: 750 | N4: 350 | O4: 1 | P4: charger | Q4: level2 | R4: =700*1.25 -> 875 | S4: =ROUNDUP(R4*(1+$X$1),-2) -> 1000 | T4: =500*1.25 -> 625 | U4: =ROUNDUP(T4*(1+$X$1),-2) -> 700 | V4: =900*1.25 -> 1125 | W4: =ROUNDUP(V4*(1+$X$1),-2) -> 1300
A5: csev-ac-sp-48a-wall | B5: MaxiCharger ACUltra - CSEV-AC-SP - 48A Output - Single Port Wall Mount | C5: MaxiCharger ACUltra - CSEV-AC-SP - 48A Output - Single Port Wall Mount. Includes 3 Years of Parts Only Warranty | D5: Autel | E5: =ROUND('EVSE Products-NY'!E5*(1+$A$53),0) -> 3332 | F5: 900 | G5: 250 | H5: 250 | I5: 750 | J5: 1250 | K5: 150 | L5: 450 | M5: 750 | N5: 350 | O5: 1 | P5: charger | Q5: level2 | R5: =700*1.25 -> 875 | S5: =ROUNDUP(R5*(1+$X$1),-2) -> 1000 | T5: =500*1.25 -> 625 | U5: =ROUNDUP(T5*(1+$X$1),-2) -> 700 | V5: =900*1.25 -> 1125 | W5: =ROUNDUP(V5*(1+$X$1),-2) -> 1300
A6: csev-ac-sp-40a-pedestal | B6: MaxiCharger ACUltra - CSEV-AC-SP - 40A Output - Single Port Pedestal with CMS | C6: MaxiCharger ACUltra - CSEV-AC-SP - 40A Output - Single Port Pedestal with CMS. Includes 3 Years of Parts Only Warranty | D6: Autel | E6: =ROUND('EVSE Products-NY'!E6*(1+$A$53),0) -> 4644 | F6: 1580 | G6: 250 | H6: 250 | I6: 750 | J6: 1250 | K6: 150 | L6: 450 | M6: 750 | N6: 350 | O6: 1 | P6: charger | Q6: level2 | R6: =700*1.25 -> 875 | S6: =ROUNDUP(R6*(1+$X$1),-2) -> 1000 | T6: =500*1.25 -> 625 | U6: =ROUNDUP(T6*(1+$X$1),-2) -> 700 | V6: =900*1.25 -> 1125 | W6: =ROUNDUP(V6*(1+$X$1),-2) -> 1300
A7: csev-ac-sp-40a-wall | B7: MaxiCharger ACUltra - CSEV-AC-SP - 40A Output - Single Port Wall Mount | C7: MaxiCharger ACUltra - CSEV-AC-SP - 40A Output - Single Port Wall Mount. Includes 3 Years of Parts Only Warranty | D7: Autel | E7: =ROUND('EVSE Products-NY'!E7*(1+$A$53),0) -> 3332 | F7: 900 | G7: 250 | H7: 250 | I7: 750 | J7: 1250 | K7: 150 | L7: 450 | M7: 750 | N7: 350 | O7: 1 | P7: charger | Q7: level2 | R7: =700*1.25 -> 875 | S7: =ROUNDUP(R7*(1+$X$1),-2) -> 1000 | T7: =500*1.25 -> 625 | U7: =ROUNDUP(T7*(1+$X$1),-2) -> 700 | V7: =900*1.25 -> 1125 | W7: =ROUNDUP(V7*(1+$X$1),-2) -> 1300
A8: csev-ac-sp-80a-pedestal | B8: MaxiCharger ACUltra - CSEV-AC-SP - 80A Output - Single Port Pedestal with CMS | C8: MaxiCharger ACUltra - CSEV-AC-SP - 80A Output - Single Port Pedestal with CMS. Includes 3 Years of Parts Only Warranty | D8: Autel | E8: =ROUND('EVSE Products-NY'!E8*(1+$A$53),0) -> 4644 | F8: 1580 | G8: 250 | H8: 250 | I8: 750 | J8: 1250 | K8: 150 | L8: 450 | M8: 750 | N8: 350 | O8: 1 | P8: charger | Q8: level2 | R8: =700*1.25 -> 875 | S8: =ROUNDUP(R8*(1+$X$1),-2) -> 1000 | T8: =500*1.25 -> 625 | U8: =ROUNDUP(T8*(1+$X$1),-2) -> 700 | V8: =900*1.25 -> 1125 | W8: =ROUNDUP(V8*(1+$X$1),-2) -> 1300
A9: csev-ac-sp-80a-wall | B9: MaxiCharger ACUltra - CSEV-AC-SP - 80A Output - Single Port Wall Mount | C9: MaxiCharger ACUltra - CSEV-AC-SP - 80A Output - Single Port Wall Mount. Includes 3 Years of Parts Only Warranty | D9: Autel | E9: =ROUND('EVSE Products-NY'!E9*(1+$A$53),0) -> 3332 | F9: 900 | G9: 250 | H9: 250 | I9: 750 | J9: 1250 | K9: 150 | L9: 450 | M9: 750 | N9: 350 | O9: 1 | P9: charger | Q9: level2 | R9: =700*1.25 -> 875 | S9: =ROUNDUP(R9*(1+$X$1),-2) -> 1000 | T9: =500*1.25 -> 625 | U9: =ROUNDUP(T9*(1+$X$1),-2) -> 700 | V9: =900*1.25 -> 1125 | W9: =ROUNDUP(V9*(1+$X$1),-2) -> 1300
A10: csev-ac-sp-32a-pedestal | B10: MaxiCharger ACUltra - CSEV-AC-SP - 32A Output - Single Port Pedestal with CMS | C10: MaxiCharger ACUltra - CSEV-AC-SP - 32A Output - Single Port Pedestal with CMS. Includes 3 Years of Parts Only Warranty | D10: Autel | E10: =ROUND('EVSE Products-NY'!E10*(1+$A$53),0) -> 4644 | F10: 1580 | G10: 250 | H10: 250 | I10: 750 | J10: 1250 | K10: 150 | L10: 450 | M10: 750 | N10: 350 | O10: 1 | P10: charger | Q10: level2 | R10: =700*1.25 -> 875 | S10: =ROUNDUP(R10*(1+$X$1),-2) -> 1000 | T10: =500*1.25 -> 625 | U10: =ROUNDUP(T10*(1+$X$1),-2) -> 700 | V10: =900*1.25 -> 1125 | W10: =ROUNDUP(V10*(1+$X$1),-2) -> 1300
A11: csev-ac-sp-32a-wall | B11: MaxiCharger ACUltra - CSEV-AC-SP - 32A Output - Single Port Wall Mount | C11: MaxiCharger ACUltra - CSEV-AC-SP - 32A Output - Single Port Wall Mount. Includes 3 Years of Parts Only Warranty | D11: Autel | E11: =ROUND('EVSE Products-NY'!E11*(1+$A$53),0) -> 3332 | F11: 900 | G11: 250 | H11: 250 | I11: 750 | J11: 1250 | K11: 150 | L11: 450 | M11: 750 | N11: 350 | O11: 1 | P11: charger | Q11: level2 | R11: =700*1.25 -> 875 | S11: =ROUNDUP(R11*(1+$X$1),-2) -> 1000 | T11: =500*1.25 -> 625 | U11: =ROUNDUP(T11*(1+$X$1),-2) -> 700 | V11: =900*1.25 -> 1125 | W11: =ROUNDUP(V11*(1+$X$1),-2) -> 1300
A12: csev-acpro-sp-50a-wall | B12: MaxiCharger ACPro - CSEV-AC-SP - 50A Output - Single Port Wall Mount | C12: MaxiCharger ACPro - CSEV-AC-SP - 50A Output - Single Port Wall Mount. Includes 3 Years of Parts Only Warranty | D12: Autel | E12: =ROUND('EVSE Products-NY'!E12*(1+$A$53),0) -> 2625 | F12: 750 | G12: 250 | H12: 250 | I12: 750 | J12: 1250 | K12: 150 | L12: 450 | M12: 750 | N12: 175 | O12: 1 | P12: charger | Q12: level2 | R12: =700*1.25 -> 875 | S12: =ROUNDUP(R12*(1+$X$1),-2) -> 1000 | T12: =500*1.25 -> 625 | U12: =ROUNDUP(T12*(1+$X$1),-2) -> 700 | V12: =900*1.25 -> 1125 | W12: =ROUNDUP(V12*(1+$X$1),-2) -> 1300
A13: csev-ac-dp-48a | B13: MaxiCharger ACUltra - CSEV-AC-DP - 48A Output - Dual Port Pedestal with CMS | C13: MaxiCharger ACUltra - CSEV-AC-DP - 48A Output - Dual Port Pedestal with CMS. Includes 3 Years of Parts Only Warranty | D13: Autel | E13: =ROUND('EVSE Products-NY'!E13*(1+$A$53),0) -> 5589 | F13: 2750 | G13: 500 | H13: 500 | I13: 1500 | J13: 2500 | K13: 300 | L13: 900 | M13: 1500 | N13: 350 | O13: 2 | P13: charger | Q13: level2 | R13: =1400*1.25 -> 1750 | S13: =R13*(1+$X$1) -> 1925 | T13: =1000*1.25 -> 1250 | U13: =T13*(1+$X$1) -> 1375 | V13: =1800*1.25 -> 2250 | W13: =V13*(1+$X$1) -> 2475
A14: csev-ac-dp-40a | B14: MaxiCharger ACUltra - CSEV-AC-DP - 40A Output - Dual Port Pedestal with CMS | C14: MaxiCharger ACUltra - CSEV-AC-DP - 40A Output - Dual Port Pedestal with CMS. Includes 3 Years of Parts Only Warranty | D14: Autel | E14: =ROUND('EVSE Products-NY'!E14*(1+$A$53),0) -> 5589 | F14: 2750 | G14: 500 | H14: 500 | I14: 1500 | J14: 2500 | K14: 300 | L14: 900 | M14: 1500 | N14: 350 | O14: 2 | P14: charger | Q14: level2 | R14: =1400*1.25 -> 1750 | S14: =R14*(1+$X$1) -> 1925 | T14: =1000*1.25 -> 1250 | U14: =T14*(1+$X$1) -> 1375 | V14: =1800*1.25 -> 2250 | W14: =V14*(1+$X$1) -> 2475
A15: csev-ac-dp-80a | B15: MaxiCharger ACUltra - CSEV-AC-DP - 80A Output - Dual Port Pedestal with CMS | C15: MaxiCharger ACUltra - CSEV-AC-DP - 80A Output - Dual Port Pedestal with CMS. Includes 3 Years of Parts Only Warranty | D15: Autel | E15: =ROUND('EVSE Products-NY'!E15*(1+$A$53),0) -> 5589 | F15: 2750 | G15: 500 | H15: 500 | I15: 1500 | J15: 2500 | K15: 300 | L15: 900 | M15: 1500 | N15: 350 | O15: 2 | P15: charger | Q15: level2 | R15: =1400*1.25 -> 1750 | S15: =R15*(1+$X$1) -> 1925 | T15: =1000*1.25 -> 1250 | U15: =T15*(1+$X$1) -> 1375 | V15: =1800*1.25 -> 2250 | W15: =V15*(1+$X$1) -> 2475
A16: csev-ac-dp-32a | B16: MaxiCharger ACUltra - CSEV-AC-DP - 32A Output - Dual Port Pedestal with CMS | C16: MaxiCharger ACUltra - CSEV-AC-DP - 32A Output - Dual Port Pedestal with CMS. Includes 3 Years of Parts Only Warranty | D16: Autel | E16: =ROUND('EVSE Products-NY'!E16*(1+$A$53),0) -> 5589 | F16: 2750 | G16: 500 | H16: 500 | I16: 1500 | J16: 2500 | K16: 300 | L16: 900 | M16: 1500 | N16: 350 | O16: 2 | P16: charger | Q16: level2 | R16: =1400*1.25 -> 1750 | S16: =R16*(1+$X$1) -> 1925 | T16: =1000*1.25 -> 1250 | U16: =T16*(1+$X$1) -> 1375 | V16: =1800*1.25 -> 2250 | W16: =V16*(1+$X$1) -> 2475
A17: csev-dcfc-60-ccs | B17: CSEV MaxiCharger 60kW DC Fast - CCS/CCS - POS & CMS & Boost Cables | C17: CSEV MaxiCharger 60kW DC Fast - CCS/CCS - POS & CMS & Boost Cables. Includes 2 Years of Parts Only Warranty | D17: Autel | E17: =ROUND('EVSE Products-NY'!E19*(1+$A$53),0) -> 50501 | F17: 36072 | G17: 680 | H17: 680 | I17: 2040 | J17: 3400 | K17: 480 | L17: 1440 | M17: 2400 | N17: 1250 | O17: 2 | P17: charger | Q17: dcfc | R17: 7700 | S17: =R17*(1+$X$1) -> 8470 | T17: 3100 | U17: =T17*(1+$X$1) -> 3410 | V17: =((R17-T17)*2)+T17 -> 12300 | W17: =V17*(1+$X$1) -> 13530
A18: csev-dcfc-120-ccs | B18: CSEV MaxiCharger 120kW DC Fast - CCS/CCS - POS & CMS & Boost Cables | C18: CSEV MaxiCharger 120kW DC Fast - CCS/CCS - POS & CMS & Boost Cables. Includes 2 Years of Parts Only Warranty | D18: Autel | E18: =ROUND('EVSE Products-NY'!E20*(1+$A$53),0) -> 54734 | F18: 39096 | G18: 680 | H18: 680 | I18: 2040 | J18: 3400 | K18: 480 | L18: 1440 | M18: 2400 | N18: 1250 | O18: 2 | P18: charger | Q18: dcfc | R18: 10000 | S18: =R18*(1+$X$1) -> 11000 | T18: 4000 | U18: =T18*(1+$X$1) -> 4400 | V18: =((R18-T18)*2)+T18 -> 16000 | W18: =V18*(1+$X$1) -> 17600
A19: csev-dcfc-180-ccs | B19: CSEV MaxiCharger 180kW DC Fast - CCS/CCS - POS & CMS & Boost Cables | C19: CSEV MaxiCharger 180kW DC Fast - CCS/CCS - POS & CMS & Boost Cables. Includes 2 Years of Parts Only Warranty | D19: Autel | E19: =ROUND('EVSE Products-NY'!E21*(1+$A$53),0) -> 67586 | F19: 48276 | G19: 680 | H19: 680 | I19: 2040 | J19: 3400 | K19: 480 | L19: 1440 | M19: 2400 | N19: 1250 | O19: 2 | P19: charger | Q19: dcfc | R19: 12200 | S19: =R19*(1+$X$1) -> 13420 | T19: 4900 | U19: =T19*(1+$X$1) -> 5390 | V19: =((R19-T19)*2)+T19 -> 19500 | W19: =V19*(1+$X$1) -> 21450
A20: csev-dcfc-240-ccs | B20: CSEV MaxiCharger 240kW DC Fast - CCS/CCS - POS & CMS & Boost Cables | C20: CSEV MaxiCharger 240kW DC Fast - CCS/CCS - POS & CMS & Boost Cables. Includes 2 Years of Parts Only Warranty | D20: Autel | E20: =ROUND('EVSE Products-NY'!E22*(1+$A$53),0) -> 83160 | F20: 59400 | G20: 680 | H20: 680 | I20: 2040 | J20: 3400 | K20: 480 | L20: 1440 | M20: 2400 | N20: 1250 | O20: 2 | P20: charger | Q20: dcfc | R20: 14500 | S20: =R20*(1+$X$1) -> 15950 | T20: 5800 | U20: =T20*(1+$X$1) -> 6380 | V20: =((R20-T20)*2)+T20 -> 23200 | W20: =V20*(1+$X$1) -> 25520
A21: csev-dcfc-60-nacs | B21: CSEV MaxiCharger 60kW DC Fast - CCS/NACS - POS & CMS & Boost Cables | C21: CSEV MaxiCharger 60kW DC Fast - CCS/NACS - POS & CMS & Boost Cables. Includes 2 Years of Parts Only Warranty | D21: Autel | E21: =ROUND('EVSE Products-NY'!E23*(1+$A$53),0) -> 50501 | F21: 36072 | G21: 680 | H21: 680 | I21: 2040 | J21: 3400 | K21: 480 | L21: 1440 | M21: 2400 | N21: 1250 | O21: 2 | P21: charger | Q21: dcfc | R21: 7700 | S21: =R21*(1+$X$1) -> 8470 | T21: 3100 | U21: =T21*(1+$X$1) -> 3410 | V21: =((R21-T21)*2)+T21 -> 12300 | W21: =V21*(1+$X$1) -> 13530
A22: csev-dcfc-120-nacs | B22: CSEV MaxiCharger 120kW DC Fast - CCS/NACS - POS & CMS & Boost Cables | C22: CSEV MaxiCharger 120kW DC Fast - CCS/NACS - POS & CMS & Boost Cables. Includes 2 Years of Parts Only Warranty | D22: Autel | E22: =ROUND('EVSE Products-NY'!E24*(1+$A$53),0) -> 54734 | F22: 39096 | G22: 680 | H22: 680 | I22: 2040 | J22: 3400 | K22: 480 | L22: 1440 | M22: 2400 | N22: 1250 | O22: 2 | P22: charger | Q22: dcfc | R22: 10000 | S22: =R22*(1+$X$1) -> 11000 | T22: 4000 | U22: =T22*(1+$X$1) -> 4400 | V22: =((R22-T22)*2)+T22 -> 16000 | W22: =V22*(1+$X$1) -> 17600
A23: csev-dcfc-180-nacs | B23: CSEV MaxiCharger 180kW DC Fast - CCS/NACS - POS & CMS & Boost Cables | C23: CSEV MaxiCharger 180kW DC Fast - CCS/NACS - POS & CMS & Boost Cables. Includes 2 Years of Parts Only Warranty | D23: Autel | E23: =ROUND('EVSE Products-NY'!E25*(1+$A$53),0) -> 67586 | F23: 48276 | G23: 680 | H23: 680 | I23: 2040 | J23: 3400 | K23: 480 | L23: 1440 | M23: 2400 | N23: 1250 | O23: 2 | P23: charger | Q23: dcfc | R23: 12200 | S23: =R23*(1+$X$1) -> 13420 | T23: 4900 | U23: =T23*(1+$X$1) -> 5390 | V23: =((R23-T23)*2)+T23 -> 19500 | W23: =V23*(1+$X$1) -> 21450
A24: csev-dcfc-240-nacs | B24: CSEV MaxiCharger 240kW DC Fast - CCS/NACS - POS & CMS & Boost Cables | C24: CSEV MaxiCharger 240kW DC Fast - CCS/NACS - POS & CMS & Boost Cables. Includes 2 Years of Parts Only Warranty | D24: Autel | E24: =ROUND('EVSE Products-NY'!E26*(1+$A$53),0) -> 83160 | F24: 59400 | G24: 680 | H24: 680 | I24: 2040 | J24: 3400 | K24: 480 | L24: 1440 | M24: 2400 | N24: 1250 | O24: 2 | P24: charger | Q24: dcfc | R24: 14500 | S24: =R24*(1+$X$1) -> 15950 | T24: 5800 | U24: =T24*(1+$X$1) -> 6380 | V24: =((R24-T24)*2)+T24 -> 23200 | W24: =V24*(1+$X$1) -> 25520
A25: csev-dchp-320-set2-ccs-ccs | B25: Set of 2 - 320kW - CSEV DCHP 320kW - CCS/CCS - POS & CMS & Boost Cables | C25: Set of 2 - CSEV DCHP 320kW - CCS/CCS - POS & CMS & Boost Cables. Includes 2 Years of Parts Only Warranty | D25: Autel | E25: =ROUND('EVSE Products-NY'!E27*(1+$A$53),0) -> 154000 | F25: 110000 | G25: 680 | H25: 680 | I25: 2040 | J25: 3400 | K25: 480 | L25: 1440 | M25: 2400 | N25: 1250 | O25: 2 | P25: charger | Q25: dcfc | R25: 25000 | S25: =R25*(1+$X$1) -> 27500 | T25: 20000 | U25: =T25*(1+$X$1) -> 22000 | V25: =((R25-T25)*2)+T25 -> 30000 | W25: =V25*(1+$X$1) -> 33000
A26: csev-dchp-320-set2-ccs-nacs | B26: Set of 2 - 320kW - CSEV DCHP 320kW - CCS/NACS - POS & CMS & Boost Cables | C26: Set of 2 - CSEV DCHP 320kW - CCS/NACS - POS & CMS & Boost Cables. Includes 2 Years of Parts Only Warranty | D26: Autel | E26: =ROUND('EVSE Products-NY'!E28*(1+$A$53),0) -> 154000 | F26: 110000 | G26: 680 | H26: 680 | I26: 2040 | J26: 3400 | K26: 480 | L26: 1440 | M26: 2400 | N26: 1250 | O26: 2 | P26: charger | Q26: dcfc | R26: 25000 | S26: =R26*(1+$X$1) -> 27500 | T26: 20000 | U26: =T26*(1+$X$1) -> 22000 | V26: =((R26-T26)*2)+T26 -> 30000 | W26: =V26*(1+$X$1) -> 33000
A27: csev-dchp-320-set2-nacs-nacs | B27: Set of 2 - 320kW - CSEV DCHP 320kW - NACS/NACS - POS & CMS & Boost Cables | C27: Set of 2 - CSEV DCHP 320kW - NACS/NACS - POS & CMS & Boost Cables. Includes 2 Years of Parts Only Warranty | D27: Autel | E27: =ROUND('EVSE Products-NY'!E29*(1+$A$53),0) -> 154000 | F27: 110000 | G27: 680 | H27: 680 | I27: 2040 | J27: 3400 | K27: 480 | L27: 1440 | M27: 2400 | N27: 1250 | O27: 2 | P27: charger | Q27: dcfc | R27: 25000 | S27: =R27*(1+$X$1) -> 27500 | T27: 20000 | U27: =T27*(1+$X$1) -> 22000 | V27: =((R27-T27)*2)+T27 -> 30000 | W27: =V27*(1+$X$1) -> 33000
A28: csev-dchp-640-set4-ccs-nacs | B28: Set of 4 - 640kW - CSEV DCHP 320kW - CCS/CCS & NACS/NACS - POS & CMS & Boost Cables | C28: Set of 4 - CSEV DCHP 320kW - CCS/CCS & NACS/NACS - POS & CMS & Boost Cables. Includes 2 Years of Parts Only Warranty | D28: Autel | E28: =ROUND('EVSE Products-NY'!E30*(1+$A$53),0) -> 206780 | F28: 147700 | G28: 1360 | H28: 1360 | I28: 4080 | J28: 6800 | K28: 960 | L28: 2880 | M28: 4800 | N28: 1250 | O28: 4 | P28: charger | Q28: dcfc | R28: =R25*2 -> 50000 | S28: =R28*(1+$X$1) -> 55000 | T28: =T25*2 -> 40000 | U28: =T28*(1+$X$1) -> 44000 | V28: =V25*2 -> 60000 | W28: =V28*(1+$X$1) -> 66000
A29: csev-dchp-640-set4-ccs-ccs | B29: Set of 4 - 640kW - CSEV DCHP 320kW - CCS/CCS & CCS/CCS - POS & CMS & Boost Cables | C29: Set of 4 - CSEV DCHP 320kW - CCS/CCS & CCS/CCS - POS & CMS & Boost Cables. Includes 2 Years of Parts Only Warranty | D29: Autel | E29: =ROUND('EVSE Products-NY'!E31*(1+$A$53),0) -> 206780 | F29: 147700 | G29: 1360 | H29: 1360 | I29: 4080 | J29: 6800 | K29: 960 | L29: 2880 | M29: 4800 | N29: 1250 | O29: 4 | P29: charger | Q29: dcfc | R29: =R26*2 -> 50000 | S29: =R29*(1+$X$1) -> 55000 | T29: =T26*2 -> 40000 | U29: =T29*(1+$X$1) -> 44000 | V29: =V26*2 -> 60000 | W29: =V29*(1+$X$1) -> 66000
A30: csev-dchp-640-set4-nacs-nacs | B30: Set of 4 - 640kW - CSEV DCHP 320kW - NACS/NACS & NACS/NACS - POS & CMS & Boost Cables | C30: Set of 4 - CSEV DCHP 320kW - NACS/NACS & NACS/NACS - POS & CMS & Boost Cables. Includes 2 Years of Parts Only Warranty | D30: Autel | E30: =ROUND('EVSE Products-NY'!E32*(1+$A$53),0) -> 206780 | F30: 147700 | G30: 1360 | H30: 1360 | I30: 4080 | J30: 6800 | K30: 960 | L30: 2880 | M30: 4800 | N30: 1250 | O30: 4 | P30: charger | Q30: dcfc | R30: =R27*2 -> 50000 | S30: =R30*(1+$X$1) -> 55000 | T30: =T27*2 -> 40000 | U30: =T30*(1+$X$1) -> 44000 | V30: =V27*2 -> 60000 | W30: =V30*(1+$X$1) -> 66000
A53: 0.05
A54: Above NY Pricing

Sheet EVSE Products-WA
A1: ID | B1: Name | C1: Description | D1: Manufacturer | E1: Unit Price ($) | F1: CSEV Cost ($) | G1: Annual Network Plan ($) | H1: Network Plan 1yr ($) | I1: Network Plan 3yr ($) | J1: Network Plan 5yr ($) | K1: Network Cost 1yr ($) | L1: Network Cost 3yr ($) | M1: Network Cost 5yr ($) | N1: Shipping ($) | O1: Number of Plugs | P1: Category | Q1: Charging Level | R1: calc1-ignore | S1: Warranty: 5-Yr Parts ONLY ($) | T1: calc2-ignore | U1: Warranty: 3-Yr FULL P&L ($) | V1: calc3-ignore | W1: Warranty: 5-Yr FULL P&L ($) | X1: 0.1
A2: csev-acpro-pedestal | B2: MaxiCharger ACPro - Pedestal | C2: Pedestal mount accessory for MaxiCharger ACPro | D2: Autel | E2: =ROUND('EVSE Products-NY'!E2*(1+$A$53),0) -> 1250 | F2: 500 | G2: 0 | H2: 0 | I2: 0 | J2: 0 | K2: 0 | L2: 0 | M2: 0 | N2: 0 | O2: 0 | P2: accessory | Q2: level2 | R2: 1000 | S2: =R2*(1+$X$1) -> 1100 | T2: 750 | U2: =T2*(1+$X$1) -> 825 | V2: 1250 | W2: =V2*(1+$X$1) -> 1375
A3: csev-acultra-cable-mgmt | B3: MaxiCharger ACUltra - Cable Management | C3: Cable management accessory for MaxiCharger ACUltra | D3: Autel | E3: =ROUND('EVSE Products-NY'!E3*(1+$A$53),0) -> 1250 | F3: 500 | G3: 0 | H3: 0 | I3: 0 | J3: 0 | K3: 0 | L3: 0 | M3: 0 | N3: 0 | O3: 0 | P3: accessory | Q3: level2 | R3: 1000 | S3: =R3*(1+$X$1) -> 1100 | T3: 750 | U3: =T3*(1+$X$1) -> 825 | V3: 1250 | W3: =V3*(1+$X$1) -> 1375
A4: csev-ac-sp-48a-pedestal | B4: MaxiCharger ACUltra - CSEV-AC-SP - 48A Output - Single Port Pedestal with CMS | C4: MaxiCharger ACUltra - CSEV-AC-SP - 48A Output - Single Port Pedestal with CMS. Includes 3 Years of Parts Only Warranty | D4: Autel | E4: =ROUND('EVSE Products-NY'!E4*(1+$A$53),0) -> 5529 | F4: 1580 | G4: 250 | H4: 250 | I4: 750 | J4: 1250 | K4: 150 | L4: 450 | M4: 750 | N4: 350 | O4: 1 | P4: charger | Q4: level2 | R4: =700*1.25 -> 875 | S4: =ROUNDUP(R4*(1+$X$1),-2) -> 1000 | T4: =500*1.25 -> 625 | U4: =ROUNDUP(T4*(1+$X$1),-2) -> 700 | V4: =900*1.25 -> 1125 | W4: =ROUNDUP(V4*(1+$X$1),-2) -> 1300
A5: csev-ac-sp-48a-wall | B5: MaxiCharger ACUltra - CSEV-AC-SP - 48A Output - Single Port Wall Mount | C5: MaxiCharger ACUltra - CSEV-AC-SP - 48A Output - Single Port Wall Mount. Includes 3 Years of Parts Only Warranty | D5: Autel | E5: =ROUND('EVSE Products-NY'!E5*(1+$A$53),0) -> 3966 | F5: 900 | G5: 250 | H5: 250 | I5: 750 | J5: 1250 | K5: 150 | L5: 450 | M5: 750 | N5: 350 | O5: 1 | P5: charger | Q5: level2 | R5: =700*1.25 -> 875 | S5: =ROUNDUP(R5*(1+$X$1),-2) -> 1000 | T5: =500*1.25 -> 625 | U5: =ROUNDUP(T5*(1+$X$1),-2) -> 700 | V5: =900*1.25 -> 1125 | W5: =ROUNDUP(V5*(1+$X$1),-2) -> 1300
A6: csev-ac-sp-40a-pedestal | B6: MaxiCharger ACUltra - CSEV-AC-SP - 40A Output - Single Port Pedestal with CMS | C6: MaxiCharger ACUltra - CSEV-AC-SP - 40A Output - Single Port Pedestal with CMS. Includes 3 Years of Parts Only Warranty | D6: Autel | E6: =ROUND('EVSE Products-NY'!E6*(1+$A$53),0) -> 5529 | F6: 1580 | G6: 250 | H6: 250 | I6: 750 | J6: 1250 | K6: 150 | L6: 450 | M6: 750 | N6: 350 | O6: 1 | P6: charger | Q6: level2 | R6: =700*1.25 -> 875 | S6: =ROUNDUP(R6*(1+$X$1),-2) -> 1000 | T6: =500*1.25 -> 625 | U6: =ROUNDUP(T6*(1+$X$1),-2) -> 700 | V6: =900*1.25 -> 1125 | W6: =ROUNDUP(V6*(1+$X$1),-2) -> 1300
A7: csev-ac-sp-40a-wall | B7: MaxiCharger ACUltra - CSEV-AC-SP - 40A Output - Single Port Wall Mount | C7: MaxiCharger ACUltra - CSEV-AC-SP - 40A Output - Single Port Wall Mount. Includes 3 Years of Parts Only Warranty | D7: Autel | E7: =ROUND('EVSE Products-NY'!E7*(1+$A$53),0) -> 3966 | F7: 900 | G7: 250 | H7: 250 | I7: 750 | J7: 1250 | K7: 150 | L7: 450 | M7: 750 | N7: 350 | O7: 1 | P7: charger | Q7: level2 | R7: =700*1.25 -> 875 | S7: =ROUNDUP(R7*(1+$X$1),-2) -> 1000 | T7: =500*1.25 -> 625 | U7: =ROUNDUP(T7*(1+$X$1),-2) -> 700 | V7: =900*1.25 -> 1125 | W7: =ROUNDUP(V7*(1+$X$1),-2) -> 1300
A8: csev-ac-sp-80a-pedestal | B8: MaxiCharger ACUltra - CSEV-AC-SP - 80A Output - Single Port Pedestal with CMS | C8: MaxiCharger ACUltra - CSEV-AC-SP - 80A Output - Single Port Pedestal with CMS. Includes 3 Years of Parts Only Warranty | D8: Autel | E8: =ROUND('EVSE Products-NY'!E8*(1+$A$53),0) -> 5529 | F8: 1580 | G8: 250 | H8: 250 | I8: 750 | J8: 1250 | K8: 150 | L8: 450 | M8: 750 | N8: 350 | O8: 1 | P8: charger | Q8: level2 | R8: =700*1.25 -> 875 | S8: =ROUNDUP(R8*(1+$X$1),-2) -> 1000 | T8: =500*1.25 -> 625 | U8: =ROUNDUP(T8*(1+$X$1),-2) -> 700 | V8: =900*1.25 -> 1125 | W8: =ROUNDUP(V8*(1+$X$1),-2) -> 1300
A9: csev-ac-sp-80a-wall | B9: MaxiCharger ACUltra - CSEV-AC-SP - 80A Output - Single Port Wall Mount | C9: MaxiCharger ACUltra - CSEV-AC-SP - 80A Output - Single Port Wall Mount. Includes 3 Years of Parts Only Warranty | D9: Autel | E9: =ROUND('EVSE Products-NY'!E9*(1+$A$53),0) -> 3966 | F9: 900 | G9: 250 | H9: 250 | I9: 750 | J9: 1250 | K9: 150 | L9: 450 | M9: 750 | N9: 350 | O9: 1 | P9: charger | Q9: level2 | R9: =700*1.25 -> 875 | S9: =ROUNDUP(R9*(1+$X$1),-2) -> 1000 | T9: =500*1.25 -> 625 | U9: =ROUNDUP(T9*(1+$X$1),-2) -> 700 | V9: =900*1.25 -> 1125 | W9: =ROUNDUP(V9*(1+$X$1),-2) -> 1300
A10: csev-ac-sp-32a-pedestal | B10: MaxiCharger ACUltra - CSEV-AC-SP - 32A Output - Single Port Pedestal with CMS | C10: MaxiCharger ACUltra - CSEV-AC-SP - 32A Output - Single Port Pedestal with CMS. Includes 3 Years of Parts Only Warranty | D10: Autel | E10: =ROUND('EVSE Products-NY'!E10*(1+$A$53),0) -> 5529 | F10: 1580 | G10: 250 | H10: 250 | I10: 750 | J10: 1250 | K10: 150 | L10: 450 | M10: 750 | N10: 350 | O10: 1 | P10: charger | Q10: level2 | R10: =700*1.25 -> 875 | S10: =ROUNDUP(R10*(1+$X$1),-2) -> 1000 | T10: =500*1.25 -> 625 | U10: =ROUNDUP(T10*(1+$X$1),-2) -> 700 | V10: =900*1.25 -> 1125 | W10: =ROUNDUP(V10*(1+$X$1),-2) -> 1300
A11: csev-ac-sp-32a-wall | B11: MaxiCharger ACUltra - CSEV-AC-SP - 32A Output - Single Port Wall Mount | C11: MaxiCharger ACUltra - CSEV-AC-SP - 32A Output - Single Port Wall Mount. Includes 3 Years of Parts Only Warranty | D11: Autel | E11: =ROUND('EVSE Products-NY'!E11*(1+$A$53),0) -> 3966 | F11: 900 | G11: 250 | H11: 250 | I11: 750 | J11: 1250 | K11: 150 | L11: 450 | M11: 750 | N11: 350 | O11: 1 | P11: charger | Q11: level2 | R11: =700*1.25 -> 875 | S11: =ROUNDUP(R11*(1+$X$1),-2) -> 1000 | T11: =500*1.25 -> 625 | U11: =ROUNDUP(T11*(1+$X$1),-2) -> 700 | V11: =900*1.25 -> 1125 | W11: =ROUNDUP(V11*(1+$X$1),-2) -> 1300
A12: csev-acpro-sp-50a-wall | B12: MaxiCharger ACPro - CSEV-AC-SP - 50A Output - Single Port Wall Mount | C12: MaxiCharger ACPro - CSEV-AC-SP - 50A Output - Single Port Wall Mount. Includes 3 Years of Parts Only Warranty | D12: Autel | E12: =ROUND('EVSE Products-NY'!E12*(1+$A$53),0) -> 3125 | F12: 750 | G12: 250 | H12: 250 | I12: 750 | J12: 1250 | K12: 150 | L12: 450 | M12: 750 | N12: 175 | O12: 1 | P12: charger | Q12: level2 | R12: =700*1.25 -> 875 | S12: =ROUNDUP(R12*(1+$X$1),-2) -> 1000 | T12: =500*1.25 -> 625 | U12: =ROUNDUP(T12*(1+$X$1),-2) -> 700 | V12: =900*1.25 -> 1125 | W12: =ROUNDUP(V12*(1+$X$1),-2) -> 1300
A13: csev-ac-dp-48a | B13: MaxiCharger ACUltra - CSEV-AC-DP - 48A Output - Dual Port Pedestal with CMS | C13: MaxiCharger ACUltra - CSEV-AC-DP - 48A Output - Dual Port Pedestal with CMS. Includes 3 Years of Parts Only Warranty | D13: Autel | E13: =ROUND('EVSE Products-NY'!E13*(1+$A$53),0) -> 6654 | F13: 2750 | G13: 500 | H13: 500 | I13: 1500 | J13: 2500 | K13: 300 | L13: 900 | M13: 1500 | N13: 350 | O13: 2 | P13: charger | Q13: level2 | R13: =1400*1.25 -> 1750 | S13: =R13*(1+$X$1) -> 1925 | T13: =1000*1.25 -> 1250 | U13: =T13*(1+$X$1) -> 1375 | V13: =1800*1.25 -> 2250 | W13: =V13*(1+$X$1) -> 2475
